--> pip install requests
Collecting requests
  Downloading requests-2.32.3-py3-none-any.whl.metadata (4.6 kB)
Requirement already satisfied: charset-normalizer<4,>=2 in ./.pythonlibs/lib/python3.12/site-packages (from requests) (3.4.1)
Requirement already satisfied: idna<4,>=2.5 in ./.pythonlibs/lib/python3.12/site-packages (from requests) (3.10)
Collecting urllib3<3,>=1.21.1 (from requests)
  Downloading urllib3-2.3.0-py3-none-any.whl.metadata (6.5 kB)
Requirement already satisfied: certifi>=2017.4.17 in ./.pythonlibs/lib/python3.12/site-packages (from requests) (2025.1.31)
Downloading requests-2.32.3-py3-none-any.whl (64 kB)
   ━━━━━━━━━━━━━━━━━━━━━━━━━━━━━━━━━━━━━━━━ 64.9/64.9 kB 2.9 MB/s eta 0:00:00
Downloading urllib3-2.3.0-py3-none-any.whl (128 kB)
   ━━━━━━━━━━━━━━━━━━━━━━━━━━━━━━━━━━━━━━━━ 128.4/128.4 kB 4.5 MB/s eta 0:00:00
Installing collected packages: urllib3, requests
Successfully installed requests-2.32.3 urllib3-2.3.0
--> pip freeze
--> pip install -r requirements.txt
ERROR: Exception:
Traceback (most recent call last):
  File "/nix/store/z0gpy18cc2s8i3y31vhad6acqvcaw6c9-python3.12-pip-24.0/lib/python3.12/site-packages/pip/_internal/cli/base_command.py", line 180, in exc_logging_wrapper
    status = run_func(*args)
             ^^^^^^^^^^^^^^^
  File "/nix/store/z0gpy18cc2s8i3y31vhad6acqvcaw6c9-python3.12-pip-24.0/lib/python3.12/site-packages/pip/_internal/cli/req_command.py", line 245, in wrapper
    return func(self, options, args)
           ^^^^^^^^^^^^^^^^^^^^^^^^^
  File "/nix/store/z0gpy18cc2s8i3y31vhad6acqvcaw6c9-python3.12-pip-24.0/lib/python3.12/site-packages/pip/_internal/commands/install.py", line 342, in run
    reqs = self.get_requirements(args, options, finder, session)
           ^^^^^^^^^^^^^^^^^^^^^^^^^^^^^^^^^^^^^^^^^^^^^^^^^^^^^
  File "/nix/store/z0gpy18cc2s8i3y31vhad6acqvcaw6c9-python3.12-pip-24.0/lib/python3.12/site-packages/pip/_internal/cli/req_command.py", line 433, in get_requirements
    for parsed_req in parse_requirements(
                      ^^^^^^^^^^^^^^^^^^^
  File "/nix/store/z0gpy18cc2s8i3y31vhad6acqvcaw6c9-python3.12-pip-24.0/lib/python3.12/site-packages/pip/_internal/req/req_file.py", line 156, in parse_requirements
    for parsed_line in parser.parse(filename, constraint):
                       ^^^^^^^^^^^^^^^^^^^^^^^^^^^^^^^^^^
  File "/nix/store/z0gpy18cc2s8i3y31vhad6acqvcaw6c9-python3.12-pip-24.0/lib/python3.12/site-packages/pip/_internal/req/req_file.py", line 337, in parse
    yield from self._parse_and_recurse(filename, constraint)
  File "/nix/store/z0gpy18cc2s8i3y31vhad6acqvcaw6c9-python3.12-pip-24.0/lib/python3.12/site-packages/pip/_internal/req/req_file.py", line 342, in _parse_and_recurse
    for line in self._parse_file(filename, constraint):
                ^^^^^^^^^^^^^^^^^^^^^^^^^^^^^^^^^^^^^^
  File "/nix/store/z0gpy18cc2s8i3y31vhad6acqvcaw6c9-python3.12-pip-24.0/lib/python3.12/site-packages/pip/_internal/req/req_file.py", line 373, in _parse_file
    _, content = get_file_content(filename, self._session)
                 ^^^^^^^^^^^^^^^^^^^^^^^^^^^^^^^^^^^^^^^^^
  File "/nix/store/z0gpy18cc2s8i3y31vhad6acqvcaw6c9-python3.12-pip-24.0/lib/python3.12/site-packages/pip/_internal/req/req_file.py", line 551, in get_file_content
    content = auto_decode(f.read())
              ^^^^^^^^^^^^^^^^^^^^^
  File "/nix/store/z0gpy18cc2s8i3y31vhad6acqvcaw6c9-python3.12-pip-24.0/lib/python3.12/site-packages/pip/_internal/utils/encoding.py", line 26, in auto_decode
    return data[len(bom) :].decode(encoding)
           ^^^^^^^^^^^^^^^^^^^^^^^^^^^^^^^^^
UnicodeDecodeError: 'utf-16-le' codec can't decode byte 0x73 in position 982: truncated data
exit status 2
