Watching for file changes with StatReloader
Performing system checks...

Exception in thread django-main-thread:
Traceback (most recent call last):
  File "/nix/store/7hnr99nxrd2aw6lghybqdmkckq60j6l9-python3-3.11.9/lib/python3.11/threading.py", line 1045, in _bootstrap_inner
    self.run()
  File "/nix/store/7hnr99nxrd2aw6lghybqdmkckq60j6l9-python3-3.11.9/lib/python3.11/threading.py", line 982, in run
    self._target(*self._args, **self._kwargs)
  File "/home/runner/workspace/.pythonlibs/lib/python3.12/site-packages/django/utils/autoreload.py", line 64, in wrapper
    fn(*args, **kwargs)
  File "/home/runner/workspace/.pythonlibs/lib/python3.12/site-packages/django/core/management/commands/runserver.py", line 134, in inner_run
    self.check(display_num_errors=True)
  File "/home/runner/workspace/.pythonlibs/lib/python3.12/site-packages/django/core/management/base.py", line 486, in check
    all_issues = checks.run_checks(
                 ^^^^^^^^^^^^^^^^^^
  File "/home/runner/workspace/.pythonlibs/lib/python3.12/site-packages/django/core/checks/registry.py", line 88, in run_checks
    new_errors = check(app_configs=app_configs, databases=databases)
                 ^^^^^^^^^^^^^^^^^^^^^^^^^^^^^^^^^^^^^^^^^^^^^^^^^^^
  File "/home/runner/workspace/.pythonlibs/lib/python3.12/site-packages/django/contrib/auth/checks.py", line 243, in check_middleware
    login_required_index = _subclass_index(
                           ^^^^^^^^^^^^^^^^
  File "/home/runner/workspace/.pythonlibs/lib/python3.12/site-packages/django/contrib/auth/checks.py", line 20, in _subclass_index
    candidate_cls = import_string(path)
                    ^^^^^^^^^^^^^^^^^^^
  File "/home/runner/workspace/.pythonlibs/lib/python3.12/site-packages/django/utils/module_loading.py", line 30, in import_string
    return cached_import(module_path, class_name)
           ^^^^^^^^^^^^^^^^^^^^^^^^^^^^^^^^^^^^^^
  File "/home/runner/workspace/.pythonlibs/lib/python3.12/site-packages/django/utils/module_loading.py", line 15, in cached_import
    module = import_module(module_path)
             ^^^^^^^^^^^^^^^^^^^^^^^^^^
  File "/nix/store/7hnr99nxrd2aw6lghybqdmkckq60j6l9-python3-3.11.9/lib/python3.11/importlib/__init__.py", line 126, in import_module
    return _bootstrap._gcd_import(name[level:], package, level)
           ^^^^^^^^^^^^^^^^^^^^^^^^^^^^^^^^^^^^^^^^^^^^^^^^^^^^
  File "<frozen importlib._bootstrap>", line 1204, in _gcd_import
  File "<frozen importlib._bootstrap>", line 1176, in _find_and_load
  File "<frozen importlib._bootstrap>", line 1147, in _find_and_load_unlocked
  File "<frozen importlib._bootstrap>", line 690, in _load_unlocked
  File "<frozen importlib._bootstrap_external>", line 940, in exec_module
  File "<frozen importlib._bootstrap>", line 241, in _call_with_frames_removed
  File "/home/runner/workspace/.pythonlibs/lib/python3.12/site-packages/axes/middleware.py", line 7, in <module>
    from axes.helpers import get_lockout_response
  File "/home/runner/workspace/.pythonlibs/lib/python3.12/site-packages/axes/helpers.py", line 15, in <module>
    from axes.models import AccessBase
  File "/home/runner/workspace/.pythonlibs/lib/python3.12/site-packages/axes/models.py", line 24, in <module>
    class AccessFailureLog(AccessBase):
  File "/home/runner/workspace/.pythonlibs/lib/python3.12/site-packages/django/db/models/base.py", line 134, in __new__
    raise RuntimeError(
RuntimeError: Model class axes.models.AccessFailureLog doesn't declare an explicit app_label and isn't in an application in INSTALLED_APPS.